Traceback (most recent call last):
  File "C:\Users\Paul\.conda\envs\2021_13\lib\site-packages\jupyter_cache\executors\utils.py", line 56, in single_nb_execution
    record_timing=False,
  File "C:\Users\Paul\.conda\envs\2021_13\lib\site-packages\nbclient\client.py", line 1204, in execute
    return NotebookClient(nb=nb, resources=resources, km=km, **kwargs).execute()
  File "C:\Users\Paul\.conda\envs\2021_13\lib\site-packages\nbclient\util.py", line 84, in wrapped
    return just_run(coro(*args, **kwargs))
  File "C:\Users\Paul\.conda\envs\2021_13\lib\site-packages\nbclient\util.py", line 62, in just_run
    return loop.run_until_complete(coro)
  File "C:\Users\Paul\.conda\envs\2021_13\lib\asyncio\base_events.py", line 587, in run_until_complete
    return future.result()
  File "C:\Users\Paul\.conda\envs\2021_13\lib\site-packages\nbclient\client.py", line 664, in async_execute
    cell, index, execution_count=self.code_cells_executed + 1
  File "C:\Users\Paul\.conda\envs\2021_13\lib\site-packages\nbclient\client.py", line 965, in async_execute_cell
    await self._check_raise_for_error(cell, cell_index, exec_reply)
  File "C:\Users\Paul\.conda\envs\2021_13\lib\site-packages\nbclient\client.py", line 862, in _check_raise_for_error
    raise CellExecutionError.from_cell_and_msg(cell, exec_reply_content)
nbclient.exceptions.CellExecutionError: An error occurred while executing the following cell:
------------------
# import library 
import pandas as pd 
import matplotlib.pyplot as plt 
from myst_nb import glue
import plotly.express as px

#Upload data
data_cols = ["Number","Recommendation","Audit Question","Weight","Level","Description","Grade"]
datas = pd.read_csv("data/manufactoring_on_board.csv", header=0, names=data_cols, na_filter=False)

#Plot an interactive graph
figX = px.scatter(datas, x="Weight", y="Grade", color="Level")
figX

------------------

[1;31m---------------------------------------------------------------------------[0m
[1;31mModuleNotFoundError[0m                       Traceback (most recent call last)
[1;32m~\AppData\Local\Temp\ipykernel_27352\1036490612.py[0m in [0;36m<module>[1;34m[0m
[0;32m      1[0m [1;31m# import library[0m[1;33m[0m[1;33m[0m[1;33m[0m[0m
[1;32m----> 2[1;33m [1;32mimport[0m [0mpandas[0m [1;32mas[0m [0mpd[0m[1;33m[0m[1;33m[0m[0m
[0m[0;32m      3[0m [1;32mimport[0m [0mmatplotlib[0m[1;33m.[0m[0mpyplot[0m [1;32mas[0m [0mplt[0m[1;33m[0m[1;33m[0m[0m
[0;32m      4[0m [1;32mfrom[0m [0mmyst_nb[0m [1;32mimport[0m [0mglue[0m[1;33m[0m[1;33m[0m[0m
[0;32m      5[0m [1;32mimport[0m [0mplotly[0m[1;33m.[0m[0mexpress[0m [1;32mas[0m [0mpx[0m[1;33m[0m[1;33m[0m[0m

[1;31mModuleNotFoundError[0m: No module named 'pandas'
ModuleNotFoundError: No module named 'pandas'

